<?xml version="1.0" encoding="utf-8"?>
<!-- This URDF was automatically created by SolidWorks to URDF Exporter! Originally created by Stephen Brawner (brawner@gmail.com) 
     Commit Version: 1.6.0-1-g15f4949  Build Version: 1.6.7594.29634
     For more information, please see http://wiki.ros.org/sw_urdf_exporter -->
<robot
  name="sittwe">
  <link
    name="base_link">
    <inertial>
      <origin
        xyz="-0.0045317 3.4781E-06 0.082877"
        rpy="0 0 0" />
      <mass
        value="8.5781" />
      <inertia
        ixx="0.09704"
        ixy="7.9054E-05"
        ixz="2.5183E-10"
        iyy="0.10984"
        iyz="-8.4902E-12"
        izz="0.19257" />
    </inertial>
    <visual>
      <origin
        xyz="0 0 0"
        rpy="0 0 0" />
      <geometry>
        <mesh
          filename="package://sittwe_description/meshes/base_link.STL" />
      </geometry>
      <material
        name="">
        <color
          rgba="0.89804 0.91765 0.92941 1" />
      </material>
    </visual>
    <collision>
      <origin
        xyz="0 0 0"
        rpy="0 0 0" />
      <geometry>
        <mesh
          filename="package://sittwe_description/meshes/base_link.STL" />
      </geometry>
    </collision>
  </link>
  <link
    name="right_wheel">
    <inertial>
      <origin
        xyz="-9.7145E-17 -0.0009488 -1.1102E-16"
        rpy="0 0 0" />
      <mass
        value="2.8826" />
      <inertia
        ixx="0.0029015"
        ixy="-2.0464E-17"
        ixz="9.0797E-19"
        iyy="0.00525"
        iyz="-1.6351E-17"
        izz="0.0029015" />
    </inertial>
    <visual>
      <origin
        xyz="0 0 0"
        rpy="0 0 0" />
      <geometry>
        <mesh
          filename="package://sittwe_description/meshes/right_wheel.STL" />
      </geometry>
      <material
        name="">
        <color
          rgba="0.29804 0.29804 0.29804 1" />
      </material>
    </visual>
    <collision>
      <origin
        xyz="0 0 0"
        rpy="0 0 0" />
      <geometry>
        <mesh
          filename="package://sittwe_description/meshes/right_wheel.STL" />
      </geometry>
    </collision>
  </link>
  <joint
    name="right_wheel_joint"
    type="continuous">
    <origin
      xyz="-0.00019478 -0.098333 -0.025976"
      rpy="0 0 0" />
    <parent
      link="base_link" />
    <child
      link="right_wheel" />
    <axis
      xyz="0 1 0" />
  </joint>
  <link
    name="left_wheel">
    <inertial>
      <origin
        xyz="-2.7756E-17 0.0009488 -1.1102E-16"
        rpy="0 0 0" />
      <mass
        value="2.8826" />
      <inertia
        ixx="0.0029015"
        ixy="-1.3805E-17"
        ixz="3.683E-18"
        iyy="0.00525"
        iyz="-1.2586E-17"
        izz="0.0029015" />
    </inertial>
    <visual>
      <origin
        xyz="0 0 0"
        rpy="0 0 0" />
      <geometry>
        <mesh
          filename="package://sittwe_description/meshes/left_wheel.STL" />
      </geometry>
      <material
        name="">
        <color
          rgba="0.29804 0.29804 0.29804 1" />
      </material>
    </visual>
    <collision>
      <origin
        xyz="0 0 0"
        rpy="0 0 0" />
      <geometry>
        <mesh
          filename="package://sittwe_description/meshes/left_wheel.STL" />
      </geometry>
    </collision>
  </link>
  <joint
    name="left_wheel_joint"
    type="continuous">
    <origin
      xyz="0 0.098333 -0.02605"
      rpy="0 0 0" />
    <parent
      link="base_link" />
    <child
      link="left_wheel" />
    <axis
      xyz="0 1 0" />
  </joint>
</robot>